Workbook

Sheet Level 1
A1: Alibaba Website Performance
A2: LEVEL 1 — Website Score (Category Roll-Up)
A3: Auto-calculated from Level 2 Sub-Factor scores below. Overall = weighted avg of the 4 categories.
A5: Category ID | B5: Category | C5: Weight | D5: Score | E5: Status
A6: C1 | B6: Performance | C6: 0.25 | D6: ='Level 2'!E12*'Level 2'!F12 -> 4.30125 | E6: =IF(D6>=9,"Excellent",IF(D6>=7,"Good",IF(D6>=5,"Needs Improvement","Poor"))) -> Poor
A7: C2 | B7: Accessibility | C7: 0.25 | D7: ='Level 2'!E24*'Level 2'!F24 -> 3.7552083 | E7: =IF(D7>=90,"Excellent",IF(D7>=70,"Good",IF(D7>=50,"Needs Improvement","Poor"))) -> Poor
A8: C3 | B8: Best Practices | C8: 0.25 | D8: ='Level 2'!E35*'Level 2'!F35 -> 4.515 | E8: =IF(D8>=90,"Excellent",IF(D8>=70,"Good",IF(D8>=50,"Needs Improvement","Poor"))) -> Poor
A9: C4 | B9: SEO | C9: 0.25 | D9: ='Level 2'!E46*'Level 2'!F46 -> 4.49 | E9: =IF(D9>=90,"Excellent",IF(D9>=70,"Good",IF(D9>=50,"Needs Improvement","Poor"))) -> Poor
A11: OVR | B11: Overall Score | C11: 1 | D11: =SUMPRODUCT(C6:C9,D6:D9) -> 4.2653646 | E11: =IF(D11>=90,"Excellent",IF(D11>=70,"Good",IF(D11>=50,"Needs Improvement","Poor"))) -> Poor
I66: calculaition 2
I68: ='L3 Performance'!E18*'L3 Performance'!F18 -> 12.75
I69: ='L3 Performance'!E19*'L3 Performance'!F19 -> 11.25
I70: ='L3 Performance'!E20*'L3 Performance'!F20 -> 13.5
I71: ='L3 Performance'!E21*'L3 Performance'!F21 -> 9
I72: ='L3 Performance'!E22*'L3 Performance'!F22 -> 14.25
I73: ='L3 Performance'!E23*'L3 Performance'!F23 -> 7.5
I74: ='L3 Performance'!E24*'L3 Performance'!F24 -> 8
I75: ='L3 Performance'!E25*'L3 Performance'!F25 -> 9
I77: =SUM(I68:I75) -> 85.25
I81: Dummy
I83: ='L3 Performance'!E33*'L3 Performance'!F33 -> 20
I84: ='L3 Performance'!E34*'L3 Performance'!F34 -> 14.25
I85: ='L3 Performance'!E35*'L3 Performance'!F35 -> 13.5
I86: ='L3 Performance'!E36*'L3 Performance'!F36 -> 14.25
I87: ='L3 Performance'!E37*'L3 Performance'!F37 -> 9
I88: ='L3 Performance'!E38*'L3 Performance'!F38 -> 9.5
I89: ='L3 Performance'!E39*'L3 Performance'!F39 -> 9
I90: ='L3 Performance'!E40*'L3 Performance'!F40 -> 5
I92: =sum(I83:I90) -> 94.5

Sheet Level 2
A1: LEVEL 2 — Sub-Factor Breakdown
A2: Sub-Factor Score = average of its Level 3 factor scores (Reference rows excluded). Category Score above pulls from here.
A4: Performance — Sub-Factors
A5: Category ID | B5: Sub-Factor ID | C5: Metric | D5: Value | E5: Score | F5: Weight
A6: C1 | B6: P1 | C6: Largest Contentful Paint (LCP) | D6: 2.1 s | E6: ='L3 Performance'!E12*'L3 Performance'!F12 -> 22.5 | F6: 0.25
A7: C1 | B7: P2 | C7: Interaction to Next Paint (INP) | D7: 290 ms | E7: ='L3 Performance'!E27*'L3 Performance'!F27 -> 21.25 | F7: 0.25
A8: C1 | B8: P3 | C8: Cumulative Layout Shift (CLS) | D8: 0.02 | E8: ='L3 Performance'!E42*'L3 Performance'!F42 -> 18.875 | F8: 0.2
A9: C1 | B9: P4 | C9: Visual Complexity | D9: High Content Density | E9: ='L3 Performance'!E54*'L3 Performance'!F54 -> 11.85 | F9: 0.15
A10: C1 | B10: P5 | C10: Hover & Animation Experience | D10: Aggressive Zoom Effect | E10: ='L3 Performance'!E66*'L3 Performance'!F66 -> 11.55 | F10: 0.15
A12: Final Sub-Factor Score | E12: =SUM(E6:E10)/5 -> 17.205 | F12: 0.25
A15: Accessibility— Sub-Factors
A16: Category ID | B16: Sub-Factor ID | C16: Metric | D16: Value | E16: Score | F16: Weight
A17: C2 | B17: Q1 | C17: Keyboard Navigation | D17: Fully Accessible | E17: ='L3 Accessibility'!E13*'L3 Accessibility'!F13 -> 18.666667 | F17: 0.2
A18: C2 | B18: Q2 | C18: Screen Reader Compatibility | D18: Compatible | E18: ='L3 Accessibility'!E26*'L3 Accessibility'!F26 -> 17.833333 | F18: 0.2
A19: C2 | B19: Q3 | C19: Color Contrast (WCAG 2.2 AA) | D19: Pass | E19: ='L3 Accessibility'!E39*'L3 Accessibility'!F39 -> 18 | F19: 0.2
A20: C2 | B20: Q4 | C20: Semantic HTML & WAI-ARIA | D20: Mostly Compliant | E20: ='L3 Accessibility'!E52*'L3 Accessibility'!F52 -> 13.125 | F20: 0.15
A21: C2 | B21: Q5 | C21: Forms & Interactive Elements | D21: Minor Accessibility Issues | E21: ='L3 Accessibility'!E64*'L3 Accessibility'!F64 -> 13.5 | F21: 0.15
A22: C2 | B22: Q6 | C22: Alternative Text & Media Accessibility | D22: Complete | E22: ='L3 Accessibility'!E76*'L3 Accessibility'!F76 -> 9 | F22: 0.1
A24: Final Sub-Factor Score | E24: =SUM(E17:E22)/6 -> 15.020833 | F24: 0.25
A27: Best Practices— Sub-Factors
A28: Category ID | B28: Sub-Factor ID | C28: Metric | D28: Value | E28: Score | F28: Weight
A29: C3 | B29: R1 | C29: Browser Console Errors | D29: No Critical Errors | E29: ='L3 Best Practices'!E12*'L3 Best Practices'!F12 -> 18.2 | F29: 0.2
A30: C3 | B30: R2 | C30: HTTPS & Secure Resources | D30: Fully Secure | E30: ='L3 Best Practices'!E24*'L3 Best Practices'!F24 -> 22.75 | F30: 0.25
A31: C3 | B31: R3 | C31: JavaScript & API Best Practices | D31: Mostly Optimized | E31: ='L3 Best Practices'!E36*'L3 Best Practices'!F36 -> 22.5 | F31: 0.25
A32: C3 | B32: R4 | C32: Modern Web Standards Compliance | D32: Mostly Compliant | E32: ='L3 Best Practices'!E48*'L3 Best Practices'!F48 -> 13.35 | F32: 0.15
A33: C3 | B33: R5 | C33: Third-Party Libraries & Dependencies | D33: Up-to-Date | E33: ='L3 Best Practices'!E60*'L3 Best Practices'!F60 -> 13.5 | F33: 0.15
A35: Final Sub-Factor Score | E35: =SUM(E29:E33)/5 -> 18.06 | F35: 0.25
A38: SEO— Sub-Factors
A39: Category ID | B39: Sub-Factor ID | C39: Metric | D39: Value | E39: Score | F39: Weight
A40: C4 | B40: S1 | C40: Meta Tags Optimization | D40: Well Optimized | E40: ='L3 SEO'!E12*'L3 SEO'!F12 -> 22.5 | F40: 0.25
A41: C4 | B41: S2 | C41: Structured Data (Schema Markup) | D41: Partially Implemented | E41: ='L3 SEO'!E24*'L3 SEO'!F24 -> 17.4 | F41: 0.2
A42: C4 | B42: S3 | C42: Mobile SEO & Responsive Design | D42: Fully Responsive | E42: ='L3 SEO'!E36*'L3 SEO'!F36 -> 18.4 | F42: 0.2
A43: C4 | B43: S4 | C43: Content Optimization | D43: Well Optimized | E43: ='L3 SEO'!E48*'L3 SEO'!F48 -> 18 | F43: 0.2
A44: C4 | B44: S5 | C44: Internal Linking & URL Structure | D44: Good Structure | E44: ='L3 SEO'!E60*'L3 SEO'!F60 -> 13.5 | F44: 0.15
A46: Final Sub-Factor Score | E46: =SUM(E40:E44)/5 -> 17.96 | F46: 0.25

Sheet L3 Performance
A1: LEVEL 3 — Details Factor ( Performance )
A3: Level 3 : Largest Contentful Paint (LCP) - P1
A4: LCP (Largest Contentful Paint)
A5: Factor id | B5: Sub Factor id | C5: Factor | D5: Value | E5: Score | F5: Weight | G5: Status
A6: ='Level 2'!$B$6 -> P1 | B6: P1A1 | C6: Server Response Time (TTFB) | D6: 450 ms | E6: 90 | F6: 0.2 | G6: =IF(E6>=90,"Excellent", IF(E6>=80," Good", IF(E6>=60,"⚠️ Needs Improvement", "❌ Poor"))) -> Excellent
A7: ='Level 2'!$B$6 -> P1 | B7: P1A2 | C7: Image Optimization | D7: WebP, Compressed | E7: 95 | F7: 0.3 | G7: =IF(E7>=90,"Excellent", IF(E7>=80," Good", IF(E7>=60,"⚠️ Needs Improvement", "❌ Poor"))) -> Excellent
A8: ='Level 2'!$B$6 -> P1 | B8: P1A3 | C8: Render Blocking CSS/JS | D8: 2 Blocking Resources | E8: 80 | F8: 0.25 | G8: =IF(E8>=90,"Excellent", IF(E8>=80," Good", IF(E8>=60,"Needs Improvement", "Poor"))) -> Good
A9: ='Level 2'!$B$6 -> P1 | B9: P1A4 | C9: Lazy Loading | D9: Implemented | E9: 90 | F9: 0.15 | G9: =IF(E9>=90,"Excellent", IF(E9>=80," Good", IF(E9>=60,"⚠️ Needs Improvement", "❌ Poor"))) -> Excellent
A10: ='Level 2'!$B$6 -> P1 | B10: P1A5 | C10: CDN & Browser Caching | D10: CDN Enabled, Cache Optimized | E10: 95 | F10: 0.1 | G10: =IF(E10>=90,"Excellent", IF(E10>=80," Good", IF(E10>=60,"⚠️ Needs Improvement", "❌ Poor"))) -> Excellent
A12: Final LCP Score | C12: Largest Contentful Paint (LCP) | E12: =sum(E6:E10)/5 -> 90 | F12: 0.25 | G12: =IF(E8>=90,"Excellent", IF(E8>=80," Good", IF(E8>=60,"Needs Improvement", "Poor"))) -> Good
A15: Level 3 : Interaction to Next Paint (INP) - P2
A16: Interaction to Next Paint (INP)
A17: Factor id | B17: Sub Factor id | C17: Factor | D17: Value | E17: Score | F17: Weight | G17: Status
A18: ='Level 2'!$B$7 -> P2 | B18: P2A1 | C18: JavaScript Execution Time | D18: 220 ms | E18: 85 | F18: 0.15 | G18: =IF(E18>=90,"Excellent", IF(E18>=80,"Good", IF(E18>=60,"Needs Improvement", "❌ Poor"))) -> Good
A19: ='Level 2'!$B$7 -> P2 | B19: P2A2 | C19: Main Thread Blocking | D19: Moderate | E19: 75 | F19: 0.15 | G19: =IF(E19>=90,"Excellent", IF(E19>=80,"Good", IF(E19>=60,"Needs Improvement", "❌ Poor"))) -> Needs Improvement
A20: ='Level 2'!$B$7 -> P2 | B20: P2A3 | C20: Event Handler Efficiency | D20: Optimized | E20: 90 | F20: 0.15 | G20: =IF(E20>=90,"Excellent", IF(E20>=80,"Good", IF(E20>=60,"Needs Improvement", "❌ Poor"))) -> Excellent
A21: ='Level 2'!$B$7 -> P2 | B21: P2A4 | C21: DOM Event Processing | D21: Fast | E21: 90 | F21: 0.1 | G21: =IF(E21>=90,"Excellent", IF(E21>=80,"Good", IF(E21>=60,"Needs Improvement", "❌ Poor"))) -> Excellent
A22: ='Level 2'!$B$7 -> P2 | B22: P2A5 | C22: Input Delay | D22: 85 ms | E22: 95 | F22: 0.15 | G22: =IF(E22>=90,"Excellent", IF(E22>=80,"Good", IF(E22>=60,"Needs Improvement", "❌ Poor"))) -> Excellent
A23: ='Level 2'!$B$7 -> P2 | B23: P2A6 | C23: Third-party Script Impact | D23: Medium | E23: 75 | F23: 0.1 | G23: =IF(E23>=90,"Excellent", IF(E23>=80,"Good", IF(E23>=60,"Needs Improvement", "❌ Poor"))) -> Needs Improvement
A24: ='Level 2'!$B$7 -> P2 | B24: P2A7 | C24: Long Tasks (>50 ms) | D24: 3 Tasks | E24: 80 | F24: 0.1 | G24: =IF(E24>=90,"Excellent", IF(E24>=80,"Good", IF(E24>=60,"Needs Improvement", "❌ Poor"))) -> Good
A25: ='Level 2'!$B$7 -> P2 | B25: P2A8 | C25: Browser Rendering Time | D25: 45 ms | E25: 90 | F25: 0.1 | G25: =IF(E25>=90,"Excellent", IF(E25>=80,"Good", IF(E25>=60,"Needs Improvement", "❌ Poor"))) -> Excellent
A27: Interaction to Next Paint (INP) | E27: =SUM(E18:E25)/8 -> 85 | F27: 0.25 | G27: =IF(E27>=90,"Excellent", IF(E27>=80,"Good", IF(E27>=60,"Needs Improvement", "❌ Poor"))) -> Good
A30: Level 3 : Cumulative Layout Shift (CLS) - P3
A31: Cumulative Layout Shift (CLS)
A32: Factor id | B32: Sub Factor id | C32: Factor | D32: Value | E32: Score | F32: Weight | G32: Status
A33: ='Level 2'!$B$8 -> P3 | B33: P3A1 | C33: Image Dimension Attributes | D33: Implemented | E33: 100 | F33: 0.2 | G33: =IF(E33>=90,"Excellent", IF(E33>=80,"Good", IF(E33>=60,"Needs Improvement", "Poor"))) -> Excellent
A34: ='Level 2'!$B$8 -> P3 | B34: P3A2 | C34: Ad/Embed Reserved Space | D34: Reserved | E34: 95 | F34: 0.15 | G34: =IF(E34>=90,"Excellent", IF(E34>=80,"Good", IF(E34>=60,"Needs Improvement", "Poor"))) -> Excellent
A35: ='Level 2'!$B$8 -> P3 | B35: P3A3 | C35: Font Loading Stability | D35: Good | E35: 90 | F35: 0.15 | G35: =IF(E35>=90,"Excellent", IF(E35>=80,"Good", IF(E35>=60,"Needs Improvement", "Poor"))) -> Excellent
A36: ='Level 2'!$B$8 -> P3 | B36: P3A4 | C36: Dynamic Content Stability | D36: Stable | E36: 95 | F36: 0.15 | G36: =IF(E36>=90,"Excellent", IF(E36>=80,"Good", IF(E36>=60,"Needs Improvement", "Poor"))) -> Excellent
A37: ='Level 2'!$B$8 -> P3 | B37: P3A5 | C37: Animation Layout Impact | D37: Minimal | E37: 90 | F37: 0.1 | G37: =IF(E37>=90,"Excellent", IF(E37>=80,"Good", IF(E37>=60,"Needs Improvement", "Poor"))) -> Excellent
A38: ='Level 2'!$B$8 -> P3 | B38: P3A6 | C38: Lazy-loaded Content Shift | D38: Very Low | E38: 95 | F38: 0.1 | G38: =IF(E38>=90,"Excellent", IF(E38>=80,"Good", IF(E38>=60,"Needs Improvement", "Poor"))) -> Excellent
A39: ='Level 2'!$B$8 -> P3 | B39: P3A7 | C39: DOM Reflow Frequency | D39: Low | E39: 90 | F39: 0.1 | G39: =IF(E39>=90,"Excellent", IF(E39>=80,"Good", IF(E39>=60,"Needs Improvement", "Poor"))) -> Excellent
A40: ='Level 2'!$B$8 -> P3 | B40: P3A8 | C40: Unexpected Layout Shifts | D40: None | E40: 100 | F40: 0.05 | G40: =IF(E40>=90,"Excellent", IF(E40>=80,"Good", IF(E40>=60,"Needs Improvement", "Poor"))) -> Excellent
A42: Cumulative Layout Shift (CLS) | E42: =SUM(E33:E40)/8 -> 94.375 | F42: 0.2 | G42: =IF(E42>=90,"Excellent", IF(E42>=80,"Good", IF(E42>=60,"Needs Improvement", "Poor"))) -> Excellent
A45: Level 3 : Visual Complexity - P4
A46: Visual Complexity
A47: Factor id | B47: Sub Factor id | C47: Factor | D47: Value | E47: Score | F47: Weight | G47: Status
A48: ='Level 2'!$B$9 -> P4 | B48: P4A1 | C48: Content Density | D48: High | E48: 65 | F48: 0.3 | G48: =IF(E48>=90,"Excellent", IF(E48>=80," Good", IF(E48>=60,"Needs Improvement", "Poor"))) -> Needs Improvement
A49: ='Level 2'!$B$9 -> P4 | B49: P4A2 | C49: White Space | D49: Moderate | E49: 75 | F49: 0.2 | G49: =IF(E49>=90,"Excellent", IF(E49>=80," Good", IF(E49>=60,"Needs Improvement", "Poor"))) -> Needs Improvement
A50: ='Level 2'!$B$9 -> P4 | B50: P4A3 | C50: Visual Hierarchy | D50: Good | E50: 85 | F50: 0.2 | G50: =IF(E50>=90,"Excellent", IF(E50>=80," Good", IF(E50>=60,"Needs Improvement", "Poor"))) -> Good
...

Sheet L3 Accessibility
A1: LEVEL 3 — Details Factor ( Accessibility )
A3: Level 3 : Keyboard Navigation - Q1
A4: Keyboard Navigation
A5: Factor id | B5: Sub Factor id | C5: Factor | D5: Value | E5: Score | F5: Weight | G5: Status
A6: ='Level 2'!$B$17 -> Q1 | B6: Q1A1 | C6: Tab Navigation | D6: Fully Functional | E6: 95 | F6: 0.2 | G6: =IF(E6>=90,"Excellent", IF(E6>=80," Good", IF(E6>=60," Needs Improvement", " Poor"))) -> Excellent
A7: ='Level 2'!$B$17 -> Q1 | B7: Q1A2 | C7: Logical Focus Order | D7: Correct | E7: 90 | F7: 0.2 | G7: =IF(E7>=90,"Excellent", IF(E7>=80," Good", IF(E7>=60," Needs Improvement", " Poor"))) -> Excellent
A8: ='Level 2'!$B$17 -> Q1 | B8: Q1A3 | C8: Visible Focus Indicator | D8: Clearly Visible | E8: 95 | F8: 0.2 | G8: =IF(E8>=90,"Excellent", IF(E8>=80," Good", IF(E8>=60," Needs Improvement", " Poor"))) -> Excellent
A9: ='Level 2'!$B$17 -> Q1 | B9: Q1A4 | C9: Skip Navigation Link | D9: Available | E9: 90 | F9: 0.15 | G9: =IF(E9>=90,"Excellent", IF(E9>=80," Good", IF(E9>=60," Needs Improvement", " Poor"))) -> Excellent
A10: ='Level 2'!$B$17 -> Q1 | B10: Q1A5 | C10: Keyboard Trap Prevention | D10: No Keyboard Traps | E10: 100 | F10: 0.15 | G10: =IF(E10>=90,"Excellent", IF(E10>=80," Good", IF(E10>=60," Needs Improvement", " Poor"))) -> Excellent
A11: ='Level 2'!$B$17 -> Q1 | B11: Q1A6 | C11: Keyboard Accessibility for Interactive Elements | D11: Fully Accessible | E11: 90 | F11: 0.1 | G11: =IF(E11>=90,"Excellent", IF(E11>=80," Good", IF(E11>=60," Needs Improvement", " Poor"))) -> Excellent
A13: Final Keyboard Navigation Score | E13: =sum(E6:E11)/6 -> 93.333333 | F13: 0.2 | G13: =IF(E13>=90,"Excellent", IF(E13>=80," Good", IF(E13>=60," Needs Improvement", " Poor"))) -> Excellent
A16: Level 3 : Screen Reader Compatibility - Q2
A17: Screen Reader Compatibility
A18: Factor id | B18: Sub Factor id | C18: Factor | D18: Value | E18: Score | F18: Weight | G18: Status
A19: ='Level 2'!$B$18 -> Q2 | C19: ARIA Labels & Roles | D19: Properly Implemented | E19: 95 | F19: 0.2 | G19: =IF(E6>=90,"Excellent", IF(E6>=80," Good", IF(E6>=60," Needs Improvement", " Poor"))) -> Excellent
A20: ='Level 2'!$B$18 -> Q2 | C20: Semantic HTML Support | D20: Fully Supported | E20: 90 | F20: 0.2 | G20: =IF(E20>=90,"Excellent", IF(E20>=80," Good", IF(E20>=60,"⚠️ Needs Improvement", "❌ Poor"))) -> Excellent
A21: ='Level 2'!$B$18 -> Q2 | C21: Image Alternative Text (Alt Text) | D21: Complete | E21: 95 | F21: 0.2 | G21: =IF(E21>=90,"Excellent", IF(E21>=80," Good", IF(E21>=60,"⚠️ Needs Improvement", "❌ Poor"))) -> Excellent
A22: ='Level 2'!$B$18 -> Q2 | C22: Form Labels & Field Descriptions | D22: Mostly Complete | E22: 85 | F22: 0.15 | G22: =IF(E22>=90,"Excellent", IF(E22>=80," Good", IF(E22>=60,"⚠️ Needs Improvement", "❌ Poor"))) -> Good
A23: ='Level 2'!$B$18 -> Q2 | C23: Dynamic Content Announcements | D23: Partially Supported | E23: 80 | F23: 0.15 | G23: =IF(E23>=90,"Excellent", IF(E23>=80," Good", IF(E23>=60,"⚠️ Needs Improvement", "❌ Poor"))) -> Good
A24: ='Level 2'!$B$18 -> Q2 | C24: Screen Reader Navigation & Reading Order | D24: Logical & Consistent | E24: 90 | F24: 0.1 | G24: =IF(E24>=90,"Excellent", IF(E24>=80," Good", IF(E24>=60,"⚠️ Needs Improvement", "❌ Poor"))) -> Excellent
A26: Final Screen Reader Compatibility Score | E26: =sum(E19:E24)/6 -> 89.166667 | F26: 0.2 | G26: =IF(E26>=90,"Excellent", IF(E26>=80," Good", IF(E26>=60,"⚠️ Needs Improvement", "❌ Poor"))) -> Good
A29: Level 3 : Color Contrast (WCAG 2.2 AA) - Q3
A30: Color Contrast (WCAG 2.2 AA)
A31: Factor id | B31: Sub Factor id | C31: Factor | D31: Value | E31: Score | F31: Weight | G31: Status
A32: ='Level 2'!$B$19 -> Q3 | B32: Q3A1 | C32: Text-to-Background Contrast Ratio | D32: WCAG AA Compliant | E32: 95 | F32: 0.2 | G32: =IF(E32>=90,"Excellent", IF(E32>=80," Good", IF(E32>=60," Needs Improvement", " Poor"))) -> Excellent
A33: ='Level 2'!$B$19 -> Q3 | B33: Q3A2 | C33: Large Text Contrast Compliance | D33: Fully Compliant | E33: 95 | F33: 0.2 | G33: =IF(E33>=90,"Excellent", IF(E33>=80," Good", IF(E33>=60," Needs Improvement", " Poor"))) -> Excellent
A34: ='Level 2'!$B$19 -> Q3 | B34: Q3A3 | C34: Interactive Elements Contrast | D34: Good Visibility | E34: 90 | F34: 0.2 | G34: =IF(E34>=90,"Excellent", IF(E34>=80," Good", IF(E34>=60," Needs Improvement", " Poor"))) -> Excellent
A35: ='Level 2'!$B$19 -> Q3 | B35: Q3A4 | C35: Link & Button Contrast | D35: Clearly Distinguishable | E35: 90 | F35: 0.15 | G35: =IF(E35>=90,"Excellent", IF(E35>=80," Good", IF(E35>=60," Needs Improvement", " Poor"))) -> Excellent
A36: ='Level 2'!$B$19 -> Q3 | B36: Q3A5 | C36: Focus Indicator Contrast | D36: Highly Visible | E36: 85 | F36: 0.15 | G36: =IF(E36>=90,"Excellent", IF(E36>=80," Good", IF(E36>=60," Needs Improvement", " Poor"))) -> Good
A37: ='Level 2'!$B$19 -> Q3 | B37: Q3A6 | C37: Non-Text UI Components Contrast | D37: Mostly Compliant | E37: 85 | F37: 0.1 | G37: =IF(E37>=90,"Excellent", IF(E37>=80," Good", IF(E37>=60," Needs Improvement", " Poor"))) -> Good
A39: Final Color Contrast (WCAG 2.2 AA) Score | E39: =sum(E32:E37)/6 -> 90 | F39: 0.2 | G39: =IF(E39>=90,"Excellent", IF(E39>=80," Good", IF(E39>=60," Needs Improvement", " Poor"))) -> Excellent
A42: Level 3 : Semantic HTML & WAI-ARIA -Q4
A43: Semantic HTML & WAI-ARIA
A44: Factor id | B44: Sub Factor id | C44: Factor | D44: Value | E44: Score | F44: Weight | G44: Status
A45: ='Level 2'!$B$20 -> Q4 | B45: Q4A1 | C45: Semantic HTML Elements Usage | D45: Properly Implemented | E45: 95 | F45: 0.2 | G45: =IF(E32>=45,"Excellent", IF(E32>=45," Good", IF(E32>=45," Needs Improvement", " Poor"))) -> Excellent
A46: ='Level 2'!$B$20 -> Q4 | B46: Q4A2 | C46: Heading Structure (H1–H6) | D46: Well Structured | E46: 90 | F46: 0.2 | G46: =IF(E33>=45,"Excellent", IF(E33>=45," Good", IF(E33>=45," Needs Improvement", " Poor"))) -> Excellent
A47: ='Level 2'!$B$20 -> Q4 | B47: Q4A3 | C47: WAI-ARIA Roles & Attributes | D47: Mostly Implemented | E47: 90 | F47: 0.2 | G47: =IF(E34>=45,"Excellent", IF(E34>=45," Good", IF(E34>=45," Needs Improvement", " Poor"))) -> Excellent
A48: ='Level 2'!$B$20 -> Q4 | B48: Q4A4 | C48: Landmark Regions (Header, Main, Nav, Footer) | D48: Clearly Defined | E48: 85 | F48: 0.15 | G48: =IF(E35>=45,"Excellent", IF(E35>=45," Good", IF(E35>=45," Needs Improvement", " Poor"))) -> Excellent
A49: ='Level 2'!$B$20 -> Q4 | B49: Q4A5 | C49: Accessible Labels & Descriptions | D49: Mostly Complete | E49: 85 | F49: 0.15 | G49: =IF(E36>=45,"Excellent", IF(E36>=45," Good", IF(E36>=45," Needs Improvement", " Poor"))) -> Excellent
A50: ='Level 2'!$B$20 -> Q4 | B50: Q4A6 | C50: HTML Validation & Accessibility Compliance | D50: Minor Issues | E50: 80 | F50: 0.1 | G50: =IF(E37>=45,"Excellent", IF(E37>=45," Good", IF(E37>=45," Needs Improvement", " Poor"))) -> Excellent
...

Sheet L3 Best Practices
A1: LEVEL 3 — Details Factor ( Best Practices )
A3: Level 3 : Browser Console Errors - R1
A4: Browser Console Errors
A5: Factor id | B5: Sub Factor id | C5: Factor | D5: Value | E5: Score | F5: Weight | G5: Status
A6: ='Level 2'!$B$29 -> R1 | B6: R1A1 | C6: JavaScript Errors | D6: No Critical Errors | E6: 95 | F6: 0.25 | G6: =IF(E6>=90,"Excellent", IF(E6>=80," Good", IF(E6>=60," Needs Improvement", " Poor"))) -> Excellent
A7: ='Level 2'!$B$29 -> R1 | B7: R1A2 | C7: CSS Errors & Warnings | D7: Minor Warnings | E7: 90 | F7: 0.2 | G7: =IF(E7>=90,"Excellent", IF(E7>=80," Good", IF(E7>=60," Needs Improvement", " Poor"))) -> Excellent
A8: ='Level 2'!$B$29 -> R1 | B8: R1A3 | C8: Network Request Errors | D8: No Failed Requests | E8: 90 | F8: 0.2 | G8: =IF(E8>=90,"Excellent", IF(E8>=80," Good", IF(E8>=60," Needs Improvement", " Poor"))) -> Excellent
A9: ='Level 2'!$B$29 -> R1 | B9: R1A4 | C9: Deprecated API Usage | D9: Not Detected | E9: 95 | F9: 0.2 | G9: =IF(E9>=90,"Excellent", IF(E9>=80," Good", IF(E9>=60," Needs Improvement", " Poor"))) -> Excellent
A10: ='Level 2'!$B$29 -> R1 | B10: R1A5 | C10: Console Warnings & Exceptions | D10: Minimal | E10: 85 | F10: 0.15 | G10: =IF(E10>=90,"Excellent", IF(E10>=80," Good", IF(E10>=60," Needs Improvement", " Poor"))) -> Good
A12: Final Browser Console Errors Score | E12: =sum(E6:E10)/5 -> 91 | F12: 0.2 | G12: =IF(E12>=90,"Excellent", IF(E12>=80," Good", IF(E12>=60," Needs Improvement", " Poor"))) -> Excellent
A15: Level 3 : HTTPS & Secure Resources - R2
A16: HTTPS & Secure Resources
A17: Factor id | B17: Sub Factor id | C17: Factor | D17: Value | E17: Score | F17: Weight | G17: Status
A18: ='Level 2'!$B$30 -> R2 | B18: R2A1 | C18: HTTPS Implementation | D18: Fully Enabled | E18: 95 | F18: 0.25 | G18: =IF(E18>=90,"Excellent", IF(E18>=80," Good", IF(E18>=60," Needs Improvement", " Poor"))) -> Excellent
A19: ='Level 2'!$B$30 -> R2 | B19: R2A2 | C19: SSL/TLS Certificate Validity | D19: Valid & Trusted | E19: 95 | F19: 0.2 | G19: =IF(E19>=90,"Excellent", IF(E19>=80," Good", IF(E19>=60," Needs Improvement", " Poor"))) -> Excellent
A20: ='Level 2'!$B$30 -> R2 | B20: R2A3 | C20: Mixed Content Protection | D20: No Mixed Content | E20: 90 | F20: 0.2 | G20: =IF(E20>=90,"Excellent", IF(E20>=80," Good", IF(E20>=60," Needs Improvement", " Poor"))) -> Excellent
A21: ='Level 2'!$B$30 -> R2 | B21: R2A4 | C21: Secure Resource Loading | D21: All Resources Secure | E21: 90 | F21: 0.2 | G21: =IF(E21>=90,"Excellent", IF(E21>=80," Good", IF(E21>=60," Needs Improvement", " Poor"))) -> Excellent
A22: ='Level 2'!$B$30 -> R2 | B22: R2A5 | C22: HTTP Security Headers | D22: Mostly Configured | E22: 85 | F22: 0.15 | G22: =IF(E22>=90,"Excellent", IF(E22>=80," Good", IF(E22>=60," Needs Improvement", " Poor"))) -> Good
A24: Final HTTPS & Secure Resources Score | E24: =SUM(E18:E22)/5 -> 91 | F24: 0.25 | G24: =IF(E24>=90,"Excellent", IF(E24>=80," Good", IF(E24>=60," Needs Improvement", " Poor"))) -> Excellent
A27: Level 3 : JavaScript & API Best Practices - R3
A28: JavaScript & API Best Practices
A29: Factor id | B29: Sub Factor id | C29: Factor | D29: Value | E29: Score | F29: Weight | G29: Status
A30: ='Level 2'!$B$31 -> R3 | B30: R3A1 | C30: Modern JavaScript Syntax (ES6+) | D30: Fully Implemented | E30: 95 | F30: 0.25 | G30: =IF(E30>=90,"Excellent", IF(E30>=80," Good", IF(E30>=60," Needs Improvement", " Poor"))) -> Excellent
A31: ='Level 2'!$B$31 -> R3 | B31: R3A2 | C31: API Request Handling | D31: Optimized | E31: 90 | F31: 0.2 | G31: =IF(E31>=90,"Excellent", IF(E31>=80," Good", IF(E31>=60," Needs Improvement", " Poor"))) -> Excellent
A32: ='Level 2'!$B$31 -> R3 | B32: R3A3 | C32: Error Handling & Exception Management | D32: Well Managed | E32: 90 | F32: 0.2 | G32: =IF(E32>=90,"Excellent", IF(E32>=80," Good", IF(E32>=60," Needs Improvement", " Poor"))) -> Excellent
A33: ='Level 2'!$B$31 -> R3 | B33: R3A4 | C33: Asynchronous Operations | D33: Efficient | E33: 85 | F33: 0.2 | G33: =IF(E33>=90,"Excellent", IF(E33>=80," Good", IF(E33>=60," Needs Improvement", " Poor"))) -> Good
A34: ='Level 2'!$B$31 -> R3 | B34: R3A5 | C34: Code Quality & Maintainability | D34: Well Structured | E34: 90 | F34: 0.15 | G34: =IF(E34>=90,"Excellent", IF(E34>=80," Good", IF(E34>=60," Needs Improvement", " Poor"))) -> Excellent
A36: Final JavaScript & API Best Practices Score | E36: =SUM(E30:E34)/5 -> 90 | F36: 0.25 | G36: =IF(E36>=90,"Excellent", IF(E36>=80," Good", IF(E36>=60," Needs Improvement", " Poor"))) -> Excellent
A39: Level 3 : Modern Web Standards Compliance -R4
A40: Modern Web Standards Compliance
A41: Factor id | B41: Sub Factor id | C41: Factor | D41: Value | E41: Score | F41: Weight | G41: Status
A42: ='Level 2'!$B$32 -> R4 | B42: R4A2 | C42: HTML5 Standards Compliance | D42: Fully Compliant | E42: 95 | F42: 0.25 | G42: =IF(E42>=90,"Excellent", IF(E42>=80," Good", IF(E42>=60," Needs Improvement", " Poor"))) -> Excellent
A43: ='Level 2'!$B$32 -> R4 | B43: R4A3 | C43: CSS3 Standards Compliance | D43: Fully Compliant | E43: 90 | F43: 0.2 | G43: =IF(E43>=90,"Excellent", IF(E43>=80," Good", IF(E43>=60," Needs Improvement", " Poor"))) -> Excellent
A44: ='Level 2'!$B$32 -> R4 | B44: R4A4 | C44: Responsive Design Standards | D44: Fully Responsive | E44: 90 | F44: 0.2 | G44: =IF(E44>=90,"Excellent", IF(E44>=80," Good", IF(E44>=60," Needs Improvement", " Poor"))) -> Excellent
A45: ='Level 2'!$B$32 -> R4 | B45: R4A5 | C45: Cross-Browser Compatibility | D45: Mostly Compatible | E45: 85 | F45: 0.2 | G45: =IF(E45>=90,"Excellent", IF(E45>=80," Good", IF(E45>=60," Needs Improvement", " Poor"))) -> Good
A46: ='Level 2'!$B$32 -> R4 | B46: R4A6 | C46: W3C Validation Compliance | D46: Minor Validation Issues | E46: 85 | F46: 0.15 | G46: =IF(E46>=90,"Excellent", IF(E46>=80," Good", IF(E46>=60," Needs Improvement", " Poor"))) -> Good
A48: Final Modern Web Standards Compliance Score | E48: =SUM(E42:E46)/5 -> 89 | F48: 0.15 | G48: =IF(E48>=90,"Excellent", IF(E48>=80," Good", IF(E48>=60," Needs Improvement", " Poor"))) -> Good
A51: Level 3 : Third-Party Libraries & Dependencies - R5
A52: Third-Party Libraries & Dependencies
A53: Factor id | B53: Sub Factor id | C53: Factor | D53: Value | E53: Score | F53: Weight | G53: Status
...

Sheet L3 SEO
A1: LEVEL 3 — Details Factor ( SEO )
A3: Level 3 : Meta Tags Optimization - S1
A4: Meta Tags Optimization
A5: Factor id | B5: Sub Factor id | C5: Factor | D5: Value | E5: Score | F5: Weight | G5: Status
A6: ='Level 2'!$B$40 -> S1 | B6: S1A1 | C6: Page Title Optimization | D6: Well Optimized | E6: 95 | F6: 0.25 | G6: =IF(E6>=90,"Excellent", IF(E6>=80," Good", IF(E6>=60," Needs Improvement", " Poor"))) -> Excellent
A7: ='Level 2'!$B$40 -> S1 | B7: S1A2 | C7: Meta Description Quality | D7: Informative & Relevant | E7: 90 | F7: 0.2 | G7: =IF(E7>=90,"Excellent", IF(E7>=80," Good", IF(E7>=60," Needs Improvement", " Poor"))) -> Excellent
A8: ='Level 2'!$B$40 -> S1 | B8: S1A3 | C8: Meta Robots Configuration | D8: Properly Configured | E8: 90 | F8: 0.2 | G8: =IF(E8>=90,"Excellent", IF(E8>=80," Good", IF(E8>=60," Needs Improvement", " Poor"))) -> Excellent
A9: ='Level 2'!$B$40 -> S1 | B9: S1A4 | C9: Open Graph & Social Meta Tags | D9: Mostly Implemented | E9: 85 | F9: 0.2 | G9: =IF(E9>=90,"Excellent", IF(E9>=80," Good", IF(E9>=60," Needs Improvement", " Poor"))) -> Good
A10: ='Level 2'!$B$40 -> S1 | B10: S1A5 | C10: Duplicate Meta Tags | D10: Not Detected | E10: 90 | F10: 0.15 | G10: =IF(E10>=90,"Excellent", IF(E10>=80," Good", IF(E10>=60," Needs Improvement", " Poor"))) -> Excellent
A12: Final Meta Tags Optimization Score | E12: =sum(E6:E10)/5 -> 90 | F12: 0.25 | G12: =IF(E12>=90,"Excellent", IF(E12>=80," Good", IF(E12>=60," Needs Improvement", " Poor"))) -> Excellent
A15: Level 3 : Structured Data (Schema Markup)
A16: Structured Data (Schema Markup)
A17: Factor id | B17: Sub Factor id | C17: Factor | D17: Value | E17: Score | F17: Weight | G17: Status
A18: ='Level 2'!$B$41 -> S2 | B18: S2A1 | C18: Schema Markup Implementation | D18: Partially Implemented | E18: 85 | F18: 0.25 | G18: =IF(E18>=90,"Excellent", IF(E18>=80," Good", IF(E18>=60," Needs Improvement", " Poor"))) -> Good
A19: ='Level 2'!$B$41 -> S2 | B19: S2A2 | C19: Organization Schema | D19: Available | E19: 90 | F19: 0.2 | G19: =IF(E19>=90,"Excellent", IF(E19>=80," Good", IF(E19>=60," Needs Improvement", " Poor"))) -> Excellent
A20: ='Level 2'!$B$41 -> S2 | B20: S2A3 | C20: Product Schema | D20: Properly Configured | E20: 90 | F20: 0.2 | G20: =IF(E20>=90,"Excellent", IF(E20>=80," Good", IF(E20>=60," Needs Improvement", " Poor"))) -> Excellent
A21: ='Level 2'!$B$41 -> S2 | B21: S2A4 | C21: Breadcrumb Schema | D21: Implemented | E21: 85 | F21: 0.2 | G21: =IF(E21>=90,"Excellent", IF(E21>=80," Good", IF(E21>=60," Needs Improvement", " Poor"))) -> Good
A22: ='Level 2'!$B$41 -> S2 | B22: S2A5 | C22: Rich Results Eligibility | D22: Mostly Eligible | E22: 85 | F22: 0.15 | G22: =IF(E22>=90,"Excellent", IF(E22>=80," Good", IF(E22>=60," Needs Improvement", " Poor"))) -> Good
A24: Final Structured Data (Schema Markup) Score | E24: =SUM(E18:E22)/5 -> 87 | F24: 0.2 | G24: =IF(E24>=90,"Excellent", IF(E24>=80," Good", IF(E24>=60," Needs Improvement", " Poor"))) -> Good
A27: Level 3 : Mobile SEO & Responsive Design -S3
A28: Mobile SEO & Responsive Design
A29: Factor id | B29: Sub Factor id | C29: Factor | D29: Value | E29: Score | F29: Weight | G29: Status
A30: ='Level 2'!$B$42 -> S3 | B30: S3A1 | C30: Mobile Responsiveness | D30: Fully Responsive | E30: 95 | F30: 0.25 | G30: =IF(E30>=90,"Excellent", IF(E30>=80," Good", IF(E30>=60," Needs Improvement", " Poor"))) -> Excellent
A31: ='Level 2'!$B$42 -> S3 | B31: S3A2 | C31: Mobile Viewport Configuration | D31: Properly Configured | E31: 95 | F31: 0.2 | G31: =IF(E31>=90,"Excellent", IF(E31>=80," Good", IF(E31>=60," Needs Improvement", " Poor"))) -> Excellent
A32: ='Level 2'!$B$42 -> S3 | B32: S3A3 | C32: Touch Element Accessibility | D32: Well Optimized | E32: 90 | F32: 0.2 | G32: =IF(E32>=90,"Excellent", IF(E32>=80," Good", IF(E32>=60," Needs Improvement", " Poor"))) -> Excellent
A33: ='Level 2'!$B$42 -> S3 | B33: S3A4 | C33: Mobile Content Consistency | D33: Consistent | E33: 90 | F33: 0.2 | G33: =IF(E33>=90,"Excellent", IF(E33>=80," Good", IF(E33>=60," Needs Improvement", " Poor"))) -> Excellent
A34: ='Level 2'!$B$42 -> S3 | B34: S3A5 | C34: Responsive Layout Stability | D34: Stable | E34: 90 | F34: 0.15 | G34: =IF(E34>=90,"Excellent", IF(E34>=80," Good", IF(E34>=60," Needs Improvement", " Poor"))) -> Excellent
A36: Final Mobile SEO & Responsive Design Score | E36: =SUM(E30:E34)/5 -> 92 | F36: 0.2 | G36: =IF(E36>=90,"Excellent", IF(E36>=80," Good", IF(E36>=60," Needs Improvement", " Poor"))) -> Excellent
A39: Level 3 : Content Optimization - S4
A40: Content Optimization
A41: Factor id | B41: Sub Factor id | C41: Factor | D41: Value | E41: Score | F41: Weight | G41: Status
A42: ='Level 2'!$B$43 -> S4 | B42: S4A1 | C42: Content Relevance | D42: Highly Relevant | E42: 95 | F42: 0.25 | G42: =IF(E42>=90,"Excellent", IF(E42>=80," Good", IF(E42>=60," Needs Improvement", " Poor"))) -> Excellent
A43: ='Level 2'!$B$43 -> S4 | B43: S4A2 | C43: Heading Structure | D43: Well Organized | E43: 90 | F43: 0.2 | G43: =IF(E43>=90,"Excellent", IF(E43>=80," Good", IF(E43>=60," Needs Improvement", " Poor"))) -> Excellent
A44: ='Level 2'!$B$43 -> S4 | B44: S4A3 | C44: Keyword Placement | D44: Naturally Optimized | E44: 90 | F44: 0.2 | G44: =IF(E44>=90,"Excellent", IF(E44>=80," Good", IF(E44>=60," Needs Improvement", " Poor"))) -> Excellent
A45: ='Level 2'!$B$43 -> S4 | B45: S4A4 | C45: Image SEO Optimization | D45: Mostly Optimized | E45: 85 | F45: 0.2 | G45: =IF(E45>=90,"Excellent", IF(E45>=80," Good", IF(E45>=60," Needs Improvement", " Poor"))) -> Good
A46: ='Level 2'!$B$43 -> S4 | B46: S4A5 | C46: Content Readability | D46: Easy to Read | E46: 90 | F46: 0.15 | G46: =IF(E46>=90,"Excellent", IF(E46>=80," Good", IF(E46>=60," Needs Improvement", " Poor"))) -> Excellent
A48: Final Content Optimization Score | E48: =SUM(E42:E46)/5 -> 90 | F48: 0.2 | G48: =IF(E48>=90,"Excellent", IF(E48>=80," Good", IF(E48>=60," Needs Improvement", " Poor"))) -> Excellent
A51: Level 3 : Internal Linking & URL Structure - S5
A52: Internal Linking & URL Structure
A53: Factor id | B53: Sub Factor id | C53: Factor | D53: Value | E53: Score | F53: Weight | G53: Status
...
